CMD-LOG-LINE-BEGIN 35751 | 2020-06-23 18:58:54,520 | INFO | az_command_data_logger | command args: interactive
CMD-LOG-LINE-BEGIN 35751 | 2020-06-23 18:58:54,529 | ERROR | cli.azure.cli.core.util | The command failed with an unexpected error. Here is the traceback:

CMD-LOG-LINE-BEGIN 35751 | 2020-06-23 18:58:54,529 | ERROR | cli.azure.cli.core.util | module 'azext_interactive' has no attribute 'start_shell'
Traceback (most recent call last):
  File "/opt/az/lib/python3.6/site-packages/knack/cli.py", line 215, in invoke
    cmd_result = self.invocation.execute(args)
  File "/opt/az/lib/python3.6/site-packages/azure/cli/core/commands/__init__.py", line 654, in execute
    raise ex
  File "/opt/az/lib/python3.6/site-packages/azure/cli/core/commands/__init__.py", line 718, in _run_jobs_serially
    results.append(self._run_job(expanded_arg, cmd_copy))
  File "/opt/az/lib/python3.6/site-packages/azure/cli/core/commands/__init__.py", line 711, in _run_job
    six.reraise(*sys.exc_info())
  File "/opt/az/lib/python3.6/site-packages/six.py", line 703, in reraise
    raise value
  File "/opt/az/lib/python3.6/site-packages/azure/cli/core/commands/__init__.py", line 688, in _run_job
    result = cmd_copy(params)
  File "/opt/az/lib/python3.6/site-packages/azure/cli/core/commands/__init__.py", line 325, in __call__
    return self.handler(*args, **kwargs)
  File "/opt/az/lib/python3.6/site-packages/azure/cli/core/__init__.py", line 545, in default_command_handler
    return op(**command_args)
  File "/opt/az/lib/python3.6/site-packages/azure/cli/command_modules/interactive/custom.py", line 41, in start_shell
    azext_interactive.start_shell(cmd, style=style)
AttributeError: module 'azext_interactive' has no attribute 'start_shell'
CMD-LOG-LINE-BEGIN 35751 | 2020-06-23 18:58:54,563 | WARNING | cli.azure.cli.core.util | 
To open an issue, please run: 'az feedback'
CMD-LOG-LINE-BEGIN 35751 | 2020-06-23 18:58:54,564 | INFO | az_command_data_logger | exit code: 1
